<?xml version="1.0"?>
<sdf version="1.7">
  <model name="diffbot">
    <static>false</static>

    <!-- Chassis (lowered and heavier) -->
    <link name="base_link">
      <pose>0 0 0.05 0 0 0</pose> <!-- only 5 cm above ground -->
      <visual name="chassis_visual">
        <geometry><box><size>0.4 0.3 0.1</size></box></geometry>
        <material>
          <ambient>0.3 0.3 0.8 1</ambient>
          <diffuse>0.4 0.4 0.9 1</diffuse>
        </material>
      </visual>
      <collision name="chassis_collision">
        <geometry><box><size>0.4 0.3 0.1</size></box></geometry>
        <surface>
          <friction><ode><mu>1.0</mu><mu2>1.0</mu2></ode></friction>
        </surface>
      </collision>
      <inertial>
        <mass>10.0</mass>
        <inertia>
          <ixx>0.5</ixx>
          <iyy>0.5</iyy>
          <izz>0.5</izz>
        </inertia>
      </inertial>
        <!-- REAL DEPTH SENSOR -->
  <sensor name="depth_camera" type="depth">
    <!-- x  y   z   roll   pitch  yaw -->
    <pose>0 0 0.20  0  0  0</pose>
    <update_rate>30</update_rate>
    <depth_camera>
      <horizontal_fov>1.047</horizontal_fov>
      <image>
        <width>640</width>
        <height>480</height>
        <!-- for float32 depth you want this format -->
        <format>R32F</format>
      </image>
      <clip>
        <near>0.1</near>
        <far>10.0</far>
      </clip>
    </depth_camera>
  </sensor>
 <sensor name="rgb_camera" type="camera">
    <!-- position it just above the body -->
    <pose>0 0 0.20  0  0  0</pose>
    <update_rate>30</update_rate>
    <camera>
      <horizontal_fov>1.047</horizontal_fov>
      <image>
        <width>640</width>
        <height>480</height>
        <format>R8G8B8</format>
      </image>
      <clip>
        <near>0.1</near>
        <far>10.0</far>
      </clip>
    </camera>
  </sensor>
      
    </link>

    <!-- Wheels (unchanged) -->
    <!-- Front Left -->
    <link name="wheel_fl">
      <pose> 0.17  0.13 0 0 0 0</pose>
      <visual name="v_fl"><pose>0 0 0 1.5707 0 0</pose>
        <geometry><cylinder><radius>0.07</radius><length>0.04</length></cylinder></geometry>
      </visual>
      <collision name="c_fl"><pose>0 0 0 1.5707 0 0</pose>
        <geometry><cylinder><radius>0.07</radius><length>0.04</length></cylinder></geometry>
        <surface><friction><ode><mu>1.0</mu><mu2>0.25</mu2></ode></friction></surface>
      </collision>
      <inertial><mass>0.2</mass></inertial>
    </link>
    <!-- Front Right -->
    <link name="wheel_fr">
      <pose> 0.17 -0.13 0 0 0 0</pose>
      <visual name="v_fr"><pose>0 0 0 1.5707 0 0</pose>
        <geometry><cylinder><radius>0.07</radius><length>0.04</length></cylinder></geometry>
      </visual>
      <collision name="c_fr"><pose>0 0 0 1.5707 0 0</pose>
        <geometry><cylinder><radius>0.07</radius><length>0.04</length></cylinder></geometry>
        <surface><friction><ode><mu>1.0</mu><mu2>0.25</mu2></ode></friction></surface>
      </collision>
      <inertial><mass>0.2</mass></inertial>
    </link>
    <!-- Rear Left -->
    <link name="wheel_rl">
      <pose>-0.17  0.13 0 0 0 0</pose>
      <visual name="v_rl"><pose>0 0 0 1.5707 0 0</pose>
        <geometry><cylinder><radius>0.07</radius><length>0.04</length></cylinder></geometry>
      </visual>
      <collision name="c_rl"><pose>0 0 0 1.5707 0 0</pose>
        <geometry><cylinder><radius>0.07</radius><length>0.04</length></cylinder></geometry>
        <surface><friction><ode><mu>0.1</mu><mu2>0.0</mu2></ode></friction></surface>
      </collision>
      <inertial><mass>0.2</mass></inertial>
    </link>
    <!-- Rear Right -->
    <link name="wheel_rr">
      <pose>-0.17 -0.13 0 0 0 0</pose>
      <visual name="v_rr"><pose>0 0 0 1.5707 0 0</pose>
        <geometry><cylinder><radius>0.07</radius><length>0.04</length></cylinder></geometry>
      </visual>
      <collision name="c_rr"><pose>0 0 0 1.5707 0 0</pose>
        <geometry><cylinder><radius>0.07</radius><length>0.04</length></cylinder></geometry>
        <surface><friction><ode><mu>0.1</mu><mu2>0.0</mu2></ode></friction></surface>
      </collision>
      <inertial><mass>0.2</mass></inertial>
    </link>

    <!-- Wheel Joints (strong damping, low effort) -->
    <joint name="joint_wheel_fl" type="revolute">
      <parent>base_link</parent><child>wheel_fl</child>
      <axis>
        <xyz>0 1 0</xyz>
        <limit>
          <lower>-1000</lower><upper>1000</upper>
          <effort>5</effort>
          <velocity>10</velocity>
        </limit>
        <dynamics><damping>2.0</damping></dynamics>
      </axis>
    </joint>
    <joint name="joint_wheel_fr" type="revolute">
      <parent>base_link</parent><child>wheel_fr</child>
      <axis>
        <xyz>0 1 0</xyz>
        <limit>
          <lower>-1000</lower><upper>1000</upper>
          <effort>5</effort>
          <velocity>10</velocity>
        </limit>
        <dynamics><damping>2.0</damping></dynamics>
      </axis>
    </joint>
    <joint name="joint_wheel_rl" type="revolute">
      <parent>base_link</parent><child>wheel_rl</child>
      <axis>
        <xyz>0 1 0</xyz>
        <limit>
          <lower>-1000</lower><upper>1000</upper>
          <effort>5</effort>
          <velocity>10</velocity>
        </limit>
        <dynamics><damping>2.0</damping></dynamics>
      </axis>
    </joint>
    <joint name="joint_wheel_rr" type="revolute">
      <parent>base_link</parent><child>wheel_rr</child>
      <axis>
        <xyz>0 1 0</xyz>
        <limit>
          <lower>-1000</lower><upper>1000</upper>
          <effort>5</effort>
          <velocity>10</velocity>
        </limit>
        <dynamics><damping>2.0</damping></dynamics>
      </axis>
    </joint>
     
    <!-- DiffDrive plugin with limited force/acceleration -->
    <plugin
      filename="libignition-gazebo-diff-drive-system.so"
      name="ignition::gazebo::systems::DiffDrive">

      <left_joint>joint_wheel_fl</left_joint>
      <left_joint>joint_wheel_rl</left_joint>

      <right_joint>joint_wheel_fr</right_joint>
      <right_joint>joint_wheel_rr</right_joint>

      <wheel_separation>0.4</wheel_separation>
      <wheel_radius>0.07</wheel_radius>

      <topic>/cmd_vel</topic>
      <odom_publish_frequency>20.0</odom_publish_frequency>
      <odom_frame_id>odom</odom_frame_id>
      <base_frame_id>base_link</base_frame_id>
      <publish_odom_tf>true</publish_odom_tf>

      <!-- gentle drive settings -->
      <min_velocity>-5.0</min_velocity>
      <max_velocity>5.0</max_velocity>
      <min_acceleration>-2.0</min_acceleration>
      <max_acceleration>2.0</max_acceleration>
      <min_force>-5.0</min_force>
      <max_force>5.0</max_force>
    </plugin>

  </model>
</sdf>

